Traceback (most recent call last):
  File "/Users/richb/.pyenv/versions/3.7.4/lib/python3.7/site-packages/urllib3/connection.py", line 170, in _new_conn
    (self._dns_host, self.port), self.timeout, **extra_kw
  File "/Users/richb/.pyenv/versions/3.7.4/lib/python3.7/site-packages/urllib3/util/connection.py", line 96, in create_connection
    raise err
  File "/Users/richb/.pyenv/versions/3.7.4/lib/python3.7/site-packages/urllib3/util/connection.py", line 86, in create_connection
    sock.connect(sa)
ConnectionRefusedError: [Errno 61] Connection refused

During handling of the above exception, another exception occurred:

Traceback (most recent call last):
  File "/Users/richb/.pyenv/versions/3.7.4/lib/python3.7/site-packages/urllib3/connectionpool.py", line 706, in urlopen
    chunked=chunked,
  File "/Users/richb/.pyenv/versions/3.7.4/lib/python3.7/site-packages/urllib3/connectionpool.py", line 382, in _make_request
    self._validate_conn(conn)
  File "/Users/richb/.pyenv/versions/3.7.4/lib/python3.7/site-packages/urllib3/connectionpool.py", line 1010, in _validate_conn
    conn.connect()
  File "/Users/richb/.pyenv/versions/3.7.4/lib/python3.7/site-packages/urllib3/connection.py", line 353, in connect
    conn = self._new_conn()
  File "/Users/richb/.pyenv/versions/3.7.4/lib/python3.7/site-packages/urllib3/connection.py", line 182, in _new_conn
    self, "Failed to establish a new connection: %s" % e
urllib3.exceptions.NewConnectionError: <urllib3.connection.HTTPSConnection object at 0x109d3c210>: Failed to establish a new connection: [Errno 61] Connection refused

During handling of the above exception, another exception occurred:

Traceback (most recent call last):
  File "/Users/richb/.pyenv/versions/3.7.4/lib/python3.7/site-packages/requests/adapters.py", line 449, in send
    timeout=timeout
  File "/Users/richb/.pyenv/versions/3.7.4/lib/python3.7/site-packages/urllib3/connectionpool.py", line 756, in urlopen
    method, url, error=e, _pool=self, _stacktrace=sys.exc_info()[2]
  File "/Users/richb/.pyenv/versions/3.7.4/lib/python3.7/site-packages/urllib3/util/retry.py", line 573, in increment
    raise MaxRetryError(_pool, url, error or ResponseError(cause))
urllib3.exceptions.MaxRetryError: HTTPSConnectionPool(host='gis.vgsi.com', port=443): Max retries exceeded with url: /lymeNH/Parcel.aspx?pid=1319 (Caused by NewConnectionError('<urllib3.connection.HTTPSConnection object at 0x109d3c210>: Failed to establish a new connection: [Errno 61] Connection refused'))

During handling of the above exception, another exception occurred:

Traceback (most recent call last):
  File "/Users/richb/github/ScrapingVGSI/scrapevgsi.py", line 402, in <module>
    sys.exit(main())
  File "/Users/richb/github/ScrapingVGSI/scrapevgsi.py", line 262, in main
    page = requests.get(url, verify=False)
  File "/Users/richb/.pyenv/versions/3.7.4/lib/python3.7/site-packages/requests/api.py", line 76, in get
    return request('get', url, params=params, **kwargs)
  File "/Users/richb/.pyenv/versions/3.7.4/lib/python3.7/site-packages/requests/api.py", line 61, in request
    return session.request(method=method, url=url, **kwargs)
  File "/Users/richb/.pyenv/versions/3.7.4/lib/python3.7/site-packages/requests/sessions.py", line 542, in request
    resp = self.send(prep, **send_kwargs)
  File "/Users/richb/.pyenv/versions/3.7.4/lib/python3.7/site-packages/requests/sessions.py", line 655, in send
    r = adapter.send(request, **kwargs)
  File "/Users/richb/.pyenv/versions/3.7.4/lib/python3.7/site-packages/requests/adapters.py", line 516, in send
    raise ConnectionError(e, request=request)
requests.exceptions.ConnectionError: HTTPSConnectionPool(host='gis.vgsi.com', port=443): Max retries exceeded with url: /lymeNH/Parcel.aspx?pid=1319 (Caused by NewConnectionError('<urllib3.connection.HTTPSConnection object at 0x109d3c210>: Failed to establish a new connection: [Errno 61] Connection refused'))

Process finished with exit code 1
